<!DOCTYPE html>
<html xmlns="http://www.w3.org/1999/xhtml" lang="en">
<head>
<meta charset="utf-8" />
<title>Re: [voidlinux/void-packages] Error while configuring python-2.7
 (#4480)</title>
<style>section{white-space:pre-wrap;}</style>
</head>
<body>
<main>
<h1>Re: [voidlinux/void-packages] Error while configuring python-2.7
 (#4480)</h1>
<section id="post1">
<h5>Alessio Sergi at <a href="#post1">Sun, 07 Aug 2016 12:21:55 -0700</a></h5>
Closed #4480 via 3191fad016417e66a6650fd9cc6b64cc1c9a7b5a.
---
You are receiving this because you commented.
Reply to this email directly or view it on GitHub:
https://github.com/voidlinux/void-packages/issues/4480#event-747751464
</section><section id="post2">
<h5>Alessio Sergi at <a href="#post2">Sun, 07 Aug 2016 12:26:12 -0700</a></h5>
`async.py` is only used with python3. You can safely ignore it.
Anyway, removed the problematic file from the python2 package to avoid all the fuss.
---
You are receiving this because you commented.
Reply to this email directly or view it on GitHub:
https://github.com/voidlinux/void-packages/issues/4480#issuecomment-238102829
</section>
</main>
<nav><a href="index.html">Issues list</a></nav>
</body>
</html>
